[2024-12-21T08:55:58.319+0000] {taskinstance.py:1159} INFO - Dependencies all met for dep_context=non-requeueable deps ti=<TaskInstance: data_ingestion_gcs_dag.bigquery_external_table_task manual__2024-12-21T08:47:07.474242+00:00 [queued]>
[2024-12-21T08:55:58.322+0000] {taskinstance.py:1159} INFO - Dependencies all met for dep_context=requeueable deps ti=<TaskInstance: data_ingestion_gcs_dag.bigquery_external_table_task manual__2024-12-21T08:47:07.474242+00:00 [queued]>
[2024-12-21T08:55:58.322+0000] {taskinstance.py:1361} INFO - Starting attempt 3 of 4
[2024-12-21T08:55:58.326+0000] {taskinstance.py:1382} INFO - Executing <Task(BigQueryCreateExternalTableOperator): bigquery_external_table_task> on 2024-12-21 08:47:07.474242+00:00
[2024-12-21T08:55:58.328+0000] {standard_task_runner.py:57} INFO - Started process 457 to run task
[2024-12-21T08:55:58.329+0000] {standard_task_runner.py:84} INFO - Running: ['***', 'tasks', 'run', 'data_ingestion_gcs_dag', 'bigquery_external_table_task', 'manual__2024-12-21T08:47:07.474242+00:00', '--job-id', '78', '--raw', '--subdir', 'DAGS_FOLDER/data_ingestion_gcs_dag.py', '--cfg-path', '/tmp/tmpzdkst2o0']
[2024-12-21T08:55:58.330+0000] {standard_task_runner.py:85} INFO - Job 78: Subtask bigquery_external_table_task
[2024-12-21T08:55:58.336+0000] {logging_mixin.py:151} WARNING - /home/***/.local/lib/python3.8/site-packages/***/settings.py:193 DeprecationWarning: The sql_alchemy_conn option in [core] has been moved to the sql_alchemy_conn option in [database] - the old setting has been used, but please update your config.
[2024-12-21T08:55:58.347+0000] {task_command.py:416} INFO - Running <TaskInstance: data_ingestion_gcs_dag.bigquery_external_table_task manual__2024-12-21T08:47:07.474242+00:00 [running]> on host 692ae35b3a44
[2024-12-21T08:55:58.370+0000] {taskinstance.py:1662} INFO - Exporting env vars: AIRFLOW_CTX_DAG_OWNER='***' AIRFLOW_CTX_DAG_ID='data_ingestion_gcs_dag' AIRFLOW_CTX_TASK_ID='bigquery_external_table_task' AIRFLOW_CTX_EXECUTION_DATE='2024-12-21T08:47:07.474242+00:00' AIRFLOW_CTX_TRY_NUMBER='3' AIRFLOW_CTX_DAG_RUN_ID='manual__2024-12-21T08:47:07.474242+00:00'
[2024-12-21T08:55:58.370+0000] {crypto.py:82} WARNING - empty cryptography key - values will not be stored encrypted.
[2024-12-21T08:55:58.371+0000] {connection.py:232} WARNING - Connection schemes (type: google_cloud_platform) shall not contain '_' according to RFC3986.
[2024-12-21T08:55:58.371+0000] {base.py:73} INFO - Using connection ID 'google_cloud_default' for task execution.
[2024-12-21T08:55:59.001+0000] {taskinstance.py:1937} ERROR - Task failed with exception
Traceback (most recent call last):
  File "/home/airflow/.local/lib/python3.8/site-packages/airflow/providers/google/cloud/operators/bigquery.py", line 1774, in execute
    table = bq_hook.create_empty_table(
  File "/home/airflow/.local/lib/python3.8/site-packages/airflow/providers/google/common/hooks/base_google.py", line 475, in inner_wrapper
    return func(self, *args, **kwargs)
  File "/home/airflow/.local/lib/python3.8/site-packages/airflow/providers/google/cloud/hooks/bigquery.py", line 420, in create_empty_table
    return self.get_client(project_id=project_id, location=location).create_table(
  File "/home/airflow/.local/lib/python3.8/site-packages/google/cloud/bigquery/client.py", line 782, in create_table
    api_response = self._call_api(
  File "/home/airflow/.local/lib/python3.8/site-packages/google/cloud/bigquery/client.py", line 816, in _call_api
    return call()
  File "/home/airflow/.local/lib/python3.8/site-packages/google/api_core/retry.py", line 366, in retry_wrapped_func
    return retry_target(
  File "/home/airflow/.local/lib/python3.8/site-packages/google/api_core/retry.py", line 204, in retry_target
    return target()
  File "/home/airflow/.local/lib/python3.8/site-packages/google/cloud/_http/__init__.py", line 494, in api_request
    raise exceptions.from_http_response(response)
google.api_core.exceptions.NotFound: 404 POST https://bigquery.googleapis.com/bigquery/v2/projects/inlaid-micron-444611-n6/datasets/trips_data_all/tables?prettyPrint=false: Not found: Dataset inlaid-micron-444611-n6:trips_data_all
[2024-12-21T08:55:59.016+0000] {taskinstance.py:1400} INFO - Marking task as UP_FOR_RETRY. dag_id=data_ingestion_gcs_dag, task_id=bigquery_external_table_task, execution_date=20241221T084707, start_date=20241221T085558, end_date=20241221T085559
[2024-12-21T08:55:59.025+0000] {standard_task_runner.py:104} ERROR - Failed to execute job 78 for task bigquery_external_table_task (404 POST https://bigquery.googleapis.com/bigquery/v2/projects/inlaid-micron-444611-n6/datasets/trips_data_all/tables?prettyPrint=false: Not found: Dataset inlaid-micron-444611-n6:trips_data_all; 457)
[2024-12-21T08:55:59.062+0000] {local_task_job_runner.py:228} INFO - Task exited with return code 1
[2024-12-21T08:55:59.073+0000] {taskinstance.py:2778} INFO - 0 downstream tasks scheduled from follow-on schedule check
