[2024-12-21T08:47:13.786+0000] {taskinstance.py:1159} INFO - Dependencies all met for dep_context=non-requeueable deps ti=<TaskInstance: data_ingestion_gcs_dag.bigquery_external_table_task manual__2024-12-21T08:47:07.474242+00:00 [queued]>
[2024-12-21T08:47:13.788+0000] {taskinstance.py:1159} INFO - Dependencies all met for dep_context=requeueable deps ti=<TaskInstance: data_ingestion_gcs_dag.bigquery_external_table_task manual__2024-12-21T08:47:07.474242+00:00 [queued]>
[2024-12-21T08:47:13.788+0000] {taskinstance.py:1361} INFO - Starting attempt 1 of 2
[2024-12-21T08:47:13.792+0000] {taskinstance.py:1382} INFO - Executing <Task(BigQueryCreateExternalTableOperator): bigquery_external_table_task> on 2024-12-21 08:47:07.474242+00:00
[2024-12-21T08:47:13.794+0000] {standard_task_runner.py:57} INFO - Started process 224 to run task
[2024-12-21T08:47:13.795+0000] {standard_task_runner.py:84} INFO - Running: ['***', 'tasks', 'run', 'data_ingestion_gcs_dag', 'bigquery_external_table_task', 'manual__2024-12-21T08:47:07.474242+00:00', '--job-id', '75', '--raw', '--subdir', 'DAGS_FOLDER/data_ingestion_gcs_dag.py', '--cfg-path', '/tmp/tmpnewkwa0_']
[2024-12-21T08:47:13.796+0000] {standard_task_runner.py:85} INFO - Job 75: Subtask bigquery_external_table_task
[2024-12-21T08:47:13.802+0000] {logging_mixin.py:151} WARNING - /home/***/.local/lib/python3.8/site-packages/***/settings.py:193 DeprecationWarning: The sql_alchemy_conn option in [core] has been moved to the sql_alchemy_conn option in [database] - the old setting has been used, but please update your config.
[2024-12-21T08:47:13.815+0000] {task_command.py:416} INFO - Running <TaskInstance: data_ingestion_gcs_dag.bigquery_external_table_task manual__2024-12-21T08:47:07.474242+00:00 [running]> on host a8e2e655538c
[2024-12-21T08:47:13.839+0000] {taskinstance.py:1662} INFO - Exporting env vars: AIRFLOW_CTX_DAG_OWNER='***' AIRFLOW_CTX_DAG_ID='data_ingestion_gcs_dag' AIRFLOW_CTX_TASK_ID='bigquery_external_table_task' AIRFLOW_CTX_EXECUTION_DATE='2024-12-21T08:47:07.474242+00:00' AIRFLOW_CTX_TRY_NUMBER='1' AIRFLOW_CTX_DAG_RUN_ID='manual__2024-12-21T08:47:07.474242+00:00'
[2024-12-21T08:47:13.840+0000] {crypto.py:82} WARNING - empty cryptography key - values will not be stored encrypted.
[2024-12-21T08:47:13.840+0000] {connection.py:232} WARNING - Connection schemes (type: google_cloud_platform) shall not contain '_' according to RFC3986.
[2024-12-21T08:47:13.840+0000] {base.py:73} INFO - Using connection ID 'google_cloud_default' for task execution.
[2024-12-21T08:47:13.841+0000] {taskinstance.py:1937} ERROR - Task failed with exception
Traceback (most recent call last):
  File "/home/airflow/.local/lib/python3.8/site-packages/airflow/providers/google/cloud/operators/bigquery.py", line 1774, in execute
    table = bq_hook.create_empty_table(
  File "/home/airflow/.local/lib/python3.8/site-packages/airflow/providers/google/common/hooks/base_google.py", line 468, in inner_wrapper
    kwargs["project_id"] = self.project_id
  File "/home/airflow/.local/lib/python3.8/site-packages/airflow/providers/google/common/hooks/base_google.py", line 361, in project_id
    _, project_id = self.get_credentials_and_project_id()
  File "/home/airflow/.local/lib/python3.8/site-packages/airflow/providers/google/common/hooks/base_google.py", line 273, in get_credentials_and_project_id
    credentials, project_id = get_credentials_and_project_id(
  File "/home/airflow/.local/lib/python3.8/site-packages/airflow/providers/google/cloud/utils/credentials_provider.py", line 362, in get_credentials_and_project_id
    return _CredentialProvider(*args, **kwargs).get_credentials_and_project()
  File "/home/airflow/.local/lib/python3.8/site-packages/airflow/providers/google/cloud/utils/credentials_provider.py", line 235, in get_credentials_and_project
    credentials, project_id = self._get_credentials_using_key_path()
  File "/home/airflow/.local/lib/python3.8/site-packages/airflow/providers/google/cloud/utils/credentials_provider.py", line 286, in _get_credentials_using_key_path
    credentials = google.oauth2.service_account.Credentials.from_service_account_file(
  File "/home/airflow/.local/lib/python3.8/site-packages/google/oauth2/service_account.py", line 260, in from_service_account_file
    info, signer = _service_account_info.from_filename(
  File "/home/airflow/.local/lib/python3.8/site-packages/google/auth/_service_account_info.py", line 78, in from_filename
    with io.open(filename, "r", encoding="utf-8") as json_file:
IsADirectoryError: [Errno 21] Is a directory: '/.google/credentials/google_credentials.json'
[2024-12-21T08:47:13.843+0000] {taskinstance.py:1400} INFO - Marking task as UP_FOR_RETRY. dag_id=data_ingestion_gcs_dag, task_id=bigquery_external_table_task, execution_date=20241221T084707, start_date=20241221T084713, end_date=20241221T084713
[2024-12-21T08:47:13.846+0000] {standard_task_runner.py:104} ERROR - Failed to execute job 75 for task bigquery_external_table_task ([Errno 21] Is a directory: '/.google/credentials/google_credentials.json'; 224)
[2024-12-21T08:47:13.854+0000] {local_task_job_runner.py:228} INFO - Task exited with return code 1
[2024-12-21T08:47:13.860+0000] {taskinstance.py:2778} INFO - 0 downstream tasks scheduled from follow-on schedule check
