[2024-12-21T08:46:34.629+0000] {taskinstance.py:1159} INFO - Dependencies all met for dep_context=non-requeueable deps ti=<TaskInstance: data_ingestion_gcs_dag.local_to_gcs_task manual__2024-12-21T08:37:55.512351+00:00 [queued]>
[2024-12-21T08:46:34.632+0000] {taskinstance.py:1159} INFO - Dependencies all met for dep_context=requeueable deps ti=<TaskInstance: data_ingestion_gcs_dag.local_to_gcs_task manual__2024-12-21T08:37:55.512351+00:00 [queued]>
[2024-12-21T08:46:34.632+0000] {taskinstance.py:1361} INFO - Starting attempt 2 of 2
[2024-12-21T08:46:34.636+0000] {taskinstance.py:1382} INFO - Executing <Task(PythonOperator): local_to_gcs_task> on 2024-12-21 08:37:55.512351+00:00
[2024-12-21T08:46:34.639+0000] {standard_task_runner.py:57} INFO - Started process 175 to run task
[2024-12-21T08:46:34.641+0000] {standard_task_runner.py:84} INFO - Running: ['***', 'tasks', 'run', 'data_ingestion_gcs_dag', 'local_to_gcs_task', 'manual__2024-12-21T08:37:55.512351+00:00', '--job-id', '72', '--raw', '--subdir', 'DAGS_FOLDER/data_ingestion_gcs_dag.py', '--cfg-path', '/tmp/tmpkx5u5hji']
[2024-12-21T08:46:34.643+0000] {standard_task_runner.py:85} INFO - Job 72: Subtask local_to_gcs_task
[2024-12-21T08:46:34.650+0000] {logging_mixin.py:151} WARNING - /home/***/.local/lib/python3.8/site-packages/***/settings.py:193 DeprecationWarning: The sql_alchemy_conn option in [core] has been moved to the sql_alchemy_conn option in [database] - the old setting has been used, but please update your config.
[2024-12-21T08:46:34.670+0000] {task_command.py:416} INFO - Running <TaskInstance: data_ingestion_gcs_dag.local_to_gcs_task manual__2024-12-21T08:37:55.512351+00:00 [running]> on host a8e2e655538c
[2024-12-21T08:46:34.704+0000] {taskinstance.py:1662} INFO - Exporting env vars: AIRFLOW_CTX_DAG_OWNER='***' AIRFLOW_CTX_DAG_ID='data_ingestion_gcs_dag' AIRFLOW_CTX_TASK_ID='local_to_gcs_task' AIRFLOW_CTX_EXECUTION_DATE='2024-12-21T08:37:55.512351+00:00' AIRFLOW_CTX_TRY_NUMBER='2' AIRFLOW_CTX_DAG_RUN_ID='manual__2024-12-21T08:37:55.512351+00:00'
[2024-12-21T08:46:34.766+0000] {data_ingestion_gcs_dag.py:52} INFO - Téléversement dans le bucket : <Bucket: dtc_data_lake_inlaid-micron-444611-n6>, fichier : /opt/***/yellow_tripdata_2024-02.parquet
[2024-12-21T08:46:34.767+0000] {taskinstance.py:1937} ERROR - Task failed with exception
Traceback (most recent call last):
  File "/home/airflow/.local/lib/python3.8/site-packages/airflow/operators/python.py", line 192, in execute
    return_value = self.execute_callable()
  File "/home/airflow/.local/lib/python3.8/site-packages/airflow/operators/python.py", line 209, in execute_callable
    return self.python_callable(*self.op_args, **self.op_kwargs)
  File "/opt/airflow/dags/data_ingestion_gcs_dag.py", line 53, in upload_to_gcs
    blob.upload_from_filename(local_file)
  File "/home/airflow/.local/lib/python3.8/site-packages/google/cloud/storage/blob.py", line 2924, in upload_from_filename
    self._handle_filename_and_upload(
  File "/home/airflow/.local/lib/python3.8/site-packages/google/cloud/storage/blob.py", line 2792, in _handle_filename_and_upload
    with open(filename, "rb") as file_obj:
FileNotFoundError: [Errno 2] No such file or directory: '/opt/airflow/yellow_tripdata_2024-02.parquet'
[2024-12-21T08:46:34.771+0000] {taskinstance.py:1400} INFO - Marking task as FAILED. dag_id=data_ingestion_gcs_dag, task_id=local_to_gcs_task, execution_date=20241221T083755, start_date=20241221T084634, end_date=20241221T084634
[2024-12-21T08:46:34.776+0000] {standard_task_runner.py:104} ERROR - Failed to execute job 72 for task local_to_gcs_task ([Errno 2] No such file or directory: '/opt/airflow/yellow_tripdata_2024-02.parquet'; 175)
[2024-12-21T08:46:34.780+0000] {local_task_job_runner.py:228} INFO - Task exited with return code 1
[2024-12-21T08:46:34.790+0000] {taskinstance.py:2778} INFO - 0 downstream tasks scheduled from follow-on schedule check
