[2024-12-21T08:00:49.227+0000] {taskinstance.py:1159} INFO - Dependencies all met for dep_context=non-requeueable deps ti=<TaskInstance: data_ingestion_gcs_dag.local_to_gcs_task manual__2024-12-21T07:55:45.602709+00:00 [queued]>
[2024-12-21T08:00:49.230+0000] {taskinstance.py:1159} INFO - Dependencies all met for dep_context=requeueable deps ti=<TaskInstance: data_ingestion_gcs_dag.local_to_gcs_task manual__2024-12-21T07:55:45.602709+00:00 [queued]>
[2024-12-21T08:00:49.230+0000] {taskinstance.py:1361} INFO - Starting attempt 2 of 2
[2024-12-21T08:00:49.234+0000] {taskinstance.py:1382} INFO - Executing <Task(PythonOperator): local_to_gcs_task> on 2024-12-21 07:55:45.602709+00:00
[2024-12-21T08:00:49.236+0000] {standard_task_runner.py:57} INFO - Started process 467 to run task
[2024-12-21T08:00:49.237+0000] {standard_task_runner.py:84} INFO - Running: ['***', 'tasks', 'run', 'data_ingestion_gcs_dag', 'local_to_gcs_task', 'manual__2024-12-21T07:55:45.602709+00:00', '--job-id', '54', '--raw', '--subdir', 'DAGS_FOLDER/data_ingestion_gcs_dag.py', '--cfg-path', '/tmp/tmp1b9flf8n']
[2024-12-21T08:00:49.238+0000] {standard_task_runner.py:85} INFO - Job 54: Subtask local_to_gcs_task
[2024-12-21T08:00:49.245+0000] {logging_mixin.py:151} WARNING - /home/***/.local/lib/python3.8/site-packages/***/settings.py:193 DeprecationWarning: The sql_alchemy_conn option in [core] has been moved to the sql_alchemy_conn option in [database] - the old setting has been used, but please update your config.
[2024-12-21T08:00:49.260+0000] {task_command.py:416} INFO - Running <TaskInstance: data_ingestion_gcs_dag.local_to_gcs_task manual__2024-12-21T07:55:45.602709+00:00 [running]> on host 9ad1d6b8490f
[2024-12-21T08:00:49.285+0000] {taskinstance.py:1662} INFO - Exporting env vars: AIRFLOW_CTX_DAG_OWNER='***' AIRFLOW_CTX_DAG_ID='data_ingestion_gcs_dag' AIRFLOW_CTX_TASK_ID='local_to_gcs_task' AIRFLOW_CTX_EXECUTION_DATE='2024-12-21T07:55:45.602709+00:00' AIRFLOW_CTX_TRY_NUMBER='2' AIRFLOW_CTX_DAG_RUN_ID='manual__2024-12-21T07:55:45.602709+00:00'
[2024-12-21T08:00:49.286+0000] {taskinstance.py:1937} ERROR - Task failed with exception
Traceback (most recent call last):
  File "/home/airflow/.local/lib/python3.8/site-packages/airflow/operators/python.py", line 192, in execute
    return_value = self.execute_callable()
  File "/home/airflow/.local/lib/python3.8/site-packages/airflow/operators/python.py", line 209, in execute_callable
    return self.python_callable(*self.op_args, **self.op_kwargs)
  File "/opt/airflow/dags/data_ingestion_gcs_dag.py", line 47, in upload_to_gcs
    client = storage.Client()
  File "/home/airflow/.local/lib/python3.8/site-packages/google/cloud/storage/client.py", line 166, in __init__
    super(Client, self).__init__(
  File "/home/airflow/.local/lib/python3.8/site-packages/google/cloud/client/__init__.py", line 320, in __init__
    _ClientProjectMixin.__init__(self, project=project, credentials=credentials)
  File "/home/airflow/.local/lib/python3.8/site-packages/google/cloud/client/__init__.py", line 268, in __init__
    project = self._determine_default(project)
  File "/home/airflow/.local/lib/python3.8/site-packages/google/cloud/client/__init__.py", line 287, in _determine_default
    return _determine_default_project(project)
  File "/home/airflow/.local/lib/python3.8/site-packages/google/cloud/_helpers/__init__.py", line 152, in _determine_default_project
    _, project = google.auth.default()
  File "/home/airflow/.local/lib/python3.8/site-packages/google/auth/_default.py", line 657, in default
    credentials, project_id = checker()
  File "/home/airflow/.local/lib/python3.8/site-packages/google/auth/_default.py", line 650, in <lambda>
    lambda: _get_explicit_environ_credentials(quota_project_id=quota_project_id),
  File "/home/airflow/.local/lib/python3.8/site-packages/google/auth/_default.py", line 270, in _get_explicit_environ_credentials
    credentials, project_id = load_credentials_from_file(
  File "/home/airflow/.local/lib/python3.8/site-packages/google/auth/_default.py", line 114, in load_credentials_from_file
    raise exceptions.DefaultCredentialsError(
google.auth.exceptions.DefaultCredentialsError: File ~/.google/credentials/google_credentials.json was not found.
[2024-12-21T08:00:49.289+0000] {taskinstance.py:1400} INFO - Marking task as FAILED. dag_id=data_ingestion_gcs_dag, task_id=local_to_gcs_task, execution_date=20241221T075545, start_date=20241221T080049, end_date=20241221T080049
[2024-12-21T08:00:49.293+0000] {standard_task_runner.py:104} ERROR - Failed to execute job 54 for task local_to_gcs_task (File ~/.google/credentials/google_credentials.json was not found.; 467)
[2024-12-21T08:00:49.296+0000] {local_task_job_runner.py:228} INFO - Task exited with return code 1
[2024-12-21T08:00:49.304+0000] {taskinstance.py:2778} INFO - 0 downstream tasks scheduled from follow-on schedule check
