[2024-12-21T07:50:45.956+0000] {taskinstance.py:1159} INFO - Dependencies all met for dep_context=non-requeueable deps ti=<TaskInstance: data_ingestion_gcs_dag.local_to_gcs_task manual__2024-12-21T07:50:42.849733+00:00 [queued]>
[2024-12-21T07:50:45.959+0000] {taskinstance.py:1159} INFO - Dependencies all met for dep_context=requeueable deps ti=<TaskInstance: data_ingestion_gcs_dag.local_to_gcs_task manual__2024-12-21T07:50:42.849733+00:00 [queued]>
[2024-12-21T07:50:45.959+0000] {taskinstance.py:1361} INFO - Starting attempt 1 of 2
[2024-12-21T07:50:45.963+0000] {taskinstance.py:1382} INFO - Executing <Task(PythonOperator): local_to_gcs_task> on 2024-12-21 07:50:42.849733+00:00
[2024-12-21T07:50:45.965+0000] {standard_task_runner.py:57} INFO - Started process 196 to run task
[2024-12-21T07:50:45.966+0000] {standard_task_runner.py:84} INFO - Running: ['***', 'tasks', 'run', 'data_ingestion_gcs_dag', 'local_to_gcs_task', 'manual__2024-12-21T07:50:42.849733+00:00', '--job-id', '45', '--raw', '--subdir', 'DAGS_FOLDER/data_ingestion_gcs_dag.py', '--cfg-path', '/tmp/tmpk7_6wqa3']
[2024-12-21T07:50:45.967+0000] {standard_task_runner.py:85} INFO - Job 45: Subtask local_to_gcs_task
[2024-12-21T07:50:45.972+0000] {logging_mixin.py:151} WARNING - /home/***/.local/lib/python3.8/site-packages/***/settings.py:193 DeprecationWarning: The sql_alchemy_conn option in [core] has been moved to the sql_alchemy_conn option in [database] - the old setting has been used, but please update your config.
[2024-12-21T07:50:45.983+0000] {task_command.py:416} INFO - Running <TaskInstance: data_ingestion_gcs_dag.local_to_gcs_task manual__2024-12-21T07:50:42.849733+00:00 [running]> on host e714a12b1284
[2024-12-21T07:50:46.006+0000] {taskinstance.py:1662} INFO - Exporting env vars: AIRFLOW_CTX_DAG_OWNER='***' AIRFLOW_CTX_DAG_ID='data_ingestion_gcs_dag' AIRFLOW_CTX_TASK_ID='local_to_gcs_task' AIRFLOW_CTX_EXECUTION_DATE='2024-12-21T07:50:42.849733+00:00' AIRFLOW_CTX_TRY_NUMBER='1' AIRFLOW_CTX_DAG_RUN_ID='manual__2024-12-21T07:50:42.849733+00:00'
[2024-12-21T07:50:46.007+0000] {taskinstance.py:1937} ERROR - Task failed with exception
Traceback (most recent call last):
  File "/home/airflow/.local/lib/python3.8/site-packages/airflow/operators/python.py", line 192, in execute
    return_value = self.execute_callable()
  File "/home/airflow/.local/lib/python3.8/site-packages/airflow/operators/python.py", line 209, in execute_callable
    return self.python_callable(*self.op_args, **self.op_kwargs)
  File "/opt/airflow/dags/data_ingestion_gcs_dag.py", line 47, in upload_to_gcs
    client = storage.Client()
  File "/home/airflow/.local/lib/python3.8/site-packages/google/cloud/storage/client.py", line 166, in __init__
    super(Client, self).__init__(
  File "/home/airflow/.local/lib/python3.8/site-packages/google/cloud/client/__init__.py", line 320, in __init__
    _ClientProjectMixin.__init__(self, project=project, credentials=credentials)
  File "/home/airflow/.local/lib/python3.8/site-packages/google/cloud/client/__init__.py", line 268, in __init__
    project = self._determine_default(project)
  File "/home/airflow/.local/lib/python3.8/site-packages/google/cloud/client/__init__.py", line 287, in _determine_default
    return _determine_default_project(project)
  File "/home/airflow/.local/lib/python3.8/site-packages/google/cloud/_helpers/__init__.py", line 152, in _determine_default_project
    _, project = google.auth.default()
  File "/home/airflow/.local/lib/python3.8/site-packages/google/auth/_default.py", line 657, in default
    credentials, project_id = checker()
  File "/home/airflow/.local/lib/python3.8/site-packages/google/auth/_default.py", line 650, in <lambda>
    lambda: _get_explicit_environ_credentials(quota_project_id=quota_project_id),
  File "/home/airflow/.local/lib/python3.8/site-packages/google/auth/_default.py", line 270, in _get_explicit_environ_credentials
    credentials, project_id = load_credentials_from_file(
  File "/home/airflow/.local/lib/python3.8/site-packages/google/auth/_default.py", line 118, in load_credentials_from_file
    with io.open(filename, "r") as file_obj:
IsADirectoryError: [Errno 21] Is a directory: '/.google/credentials/google_credentials.json'
[2024-12-21T07:50:46.010+0000] {taskinstance.py:1400} INFO - Marking task as UP_FOR_RETRY. dag_id=data_ingestion_gcs_dag, task_id=local_to_gcs_task, execution_date=20241221T075042, start_date=20241221T075045, end_date=20241221T075046
[2024-12-21T07:50:46.013+0000] {standard_task_runner.py:104} ERROR - Failed to execute job 45 for task local_to_gcs_task ([Errno 21] Is a directory: '/.google/credentials/google_credentials.json'; 196)
[2024-12-21T07:50:46.024+0000] {local_task_job_runner.py:228} INFO - Task exited with return code 1
[2024-12-21T07:50:46.032+0000] {taskinstance.py:2778} INFO - 0 downstream tasks scheduled from follow-on schedule check
