[2024-12-21T08:02:42.403+0000] {taskinstance.py:1159} INFO - Dependencies all met for dep_context=non-requeueable deps ti=<TaskInstance: data_ingestion_gcs_dag.local_to_gcs_task manual__2024-12-21T08:02:39.851947+00:00 [queued]>
[2024-12-21T08:02:42.406+0000] {taskinstance.py:1159} INFO - Dependencies all met for dep_context=requeueable deps ti=<TaskInstance: data_ingestion_gcs_dag.local_to_gcs_task manual__2024-12-21T08:02:39.851947+00:00 [queued]>
[2024-12-21T08:02:42.407+0000] {taskinstance.py:1361} INFO - Starting attempt 1 of 2
[2024-12-21T08:02:42.411+0000] {taskinstance.py:1382} INFO - Executing <Task(PythonOperator): local_to_gcs_task> on 2024-12-21 08:02:39.851947+00:00
[2024-12-21T08:02:42.413+0000] {standard_task_runner.py:57} INFO - Started process 197 to run task
[2024-12-21T08:02:42.414+0000] {standard_task_runner.py:84} INFO - Running: ['***', 'tasks', 'run', 'data_ingestion_gcs_dag', 'local_to_gcs_task', 'manual__2024-12-21T08:02:39.851947+00:00', '--job-id', '57', '--raw', '--subdir', 'DAGS_FOLDER/data_ingestion_gcs_dag.py', '--cfg-path', '/tmp/tmpfhurw12x']
[2024-12-21T08:02:42.416+0000] {standard_task_runner.py:85} INFO - Job 57: Subtask local_to_gcs_task
[2024-12-21T08:02:42.423+0000] {logging_mixin.py:151} WARNING - /home/***/.local/lib/python3.8/site-packages/***/settings.py:193 DeprecationWarning: The sql_alchemy_conn option in [core] has been moved to the sql_alchemy_conn option in [database] - the old setting has been used, but please update your config.
[2024-12-21T08:02:42.437+0000] {task_command.py:416} INFO - Running <TaskInstance: data_ingestion_gcs_dag.local_to_gcs_task manual__2024-12-21T08:02:39.851947+00:00 [running]> on host 4375eb2eea1d
[2024-12-21T08:02:42.465+0000] {taskinstance.py:1662} INFO - Exporting env vars: AIRFLOW_CTX_DAG_OWNER='***' AIRFLOW_CTX_DAG_ID='data_ingestion_gcs_dag' AIRFLOW_CTX_TASK_ID='local_to_gcs_task' AIRFLOW_CTX_EXECUTION_DATE='2024-12-21T08:02:39.851947+00:00' AIRFLOW_CTX_TRY_NUMBER='1' AIRFLOW_CTX_DAG_RUN_ID='manual__2024-12-21T08:02:39.851947+00:00'
[2024-12-21T08:02:42.526+0000] {taskinstance.py:1937} ERROR - Task failed with exception
Traceback (most recent call last):
  File "/home/airflow/.local/lib/python3.8/site-packages/airflow/operators/python.py", line 192, in execute
    return_value = self.execute_callable()
  File "/home/airflow/.local/lib/python3.8/site-packages/airflow/operators/python.py", line 209, in execute_callable
    return self.python_callable(*self.op_args, **self.op_kwargs)
  File "/opt/airflow/dags/data_ingestion_gcs_dag.py", line 51, in upload_to_gcs
    blob.upload_from_filename(local_file)
  File "/home/airflow/.local/lib/python3.8/site-packages/google/cloud/storage/blob.py", line 2924, in upload_from_filename
    self._handle_filename_and_upload(
  File "/home/airflow/.local/lib/python3.8/site-packages/google/cloud/storage/blob.py", line 2794, in _handle_filename_and_upload
    self._prep_and_do_upload(
  File "/home/airflow/.local/lib/python3.8/site-packages/google/cloud/storage/blob.py", line 2602, in _prep_and_do_upload
    created_json = self._do_upload(
  File "/home/airflow/.local/lib/python3.8/site-packages/google/cloud/storage/blob.py", line 2425, in _do_upload
    response = self._do_resumable_upload(
  File "/home/airflow/.local/lib/python3.8/site-packages/google/cloud/storage/blob.py", line 2243, in _do_resumable_upload
    upload, transport = self._initiate_resumable_upload(
  File "/home/airflow/.local/lib/python3.8/site-packages/google/cloud/storage/blob.py", line 2073, in _initiate_resumable_upload
    hostname=hostname, bucket_path=self.bucket.path, api_version=_API_VERSION
  File "/home/airflow/.local/lib/python3.8/site-packages/google/cloud/storage/bucket.py", line 1167, in path
    raise ValueError("Cannot determine path without bucket name.")
ValueError: Cannot determine path without bucket name.
[2024-12-21T08:02:42.530+0000] {taskinstance.py:1400} INFO - Marking task as UP_FOR_RETRY. dag_id=data_ingestion_gcs_dag, task_id=local_to_gcs_task, execution_date=20241221T080239, start_date=20241221T080242, end_date=20241221T080242
[2024-12-21T08:02:42.534+0000] {standard_task_runner.py:104} ERROR - Failed to execute job 57 for task local_to_gcs_task (Cannot determine path without bucket name.; 197)
[2024-12-21T08:02:42.553+0000] {local_task_job_runner.py:228} INFO - Task exited with return code 1
[2024-12-21T08:02:42.562+0000] {taskinstance.py:2778} INFO - 0 downstream tasks scheduled from follow-on schedule check
